<?xml version="1.0" encoding="utf-8"?>

<robot name="rbq10">
    <material name="black">
        <color rgba="0.0 0.0 0.0 1.0" />
    </material>
    <material name="blue">
        <color rgba="0.0 0.0 0.8 1.0" />
    </material>
    <material name="green">
        <color rgba="0.0 0.8 0.0 1.0" />
    </material>
    <material name="grey">
        <color rgba="0.2 0.2 0.2 1.0" />
    </material>
    <material name="silver">
        <color rgba="0.913725490196 0.913725490196 0.847058823529 1.0" />
    </material>
    <material name="orange">
        <color rgba="1.0 0.423529411765 0.0392156862745 1.0" />
    </material>
    <material name="brown">
        <color rgba="0.870588235294 0.811764705882 0.764705882353 1.0" />
    </material>
    <material name="red">
        <color rgba="0.8 0.0 0.0 1.0" />
    </material>
    <material name="white">
        <color rgba="1.0 1.0 1.0 1.0" />
    </material>

  <!-- Trunk -->
  <link name="trunk">
    <inertial>
      <origin xyz="-0.013265 0.0 0.011765" rpy="0 0 0" />
      <mass value="16.758" />
      <inertia
        ixx="0.163831629266"
        ixy="-0.000271071491" iyy="0.590891341306"
        ixz="0.040352639311" iyz="0.000216428332" izz="0.678714788268" />
    </inertial>
    <collision>
      <origin xyz="0.0 0.0 0.0" rpy="0 0 0" />
      <geometry>
        <box size="0.8 0.20 0.12" />
      </geometry>
    </collision>
    <visual>
      <origin xyz="0 0 0" rpy="0 0 0" />
      <geometry> 
        <mesh filename="package://rbq_description/meshes/stl/trunk.stl" scale="1 1 1"/>
      </geometry>
      <material name="silver">
        <color rgba="0.823 0.706 0.549 1" />
      </material>
    </visual>
  </link>

  <joint name="imu_joint" type="fixed"> 
    <origin xyz="0.00665 0 -0.0404" rpy="0 0 0" /> 
    <parent link="trunk" /> 
    <child link="imu_link" /> 
  </joint>

  <!-- IMU -->
  <link name="imu_link">
  </link>

  <!-- ========== HR ========== -->
  <link name="HR_hip">
    <inertial>
      <origin xyz="0.027522 -0.01681 -0.00187" rpy="0 0 0" />
      <mass value="3.669344" />
      <inertia
        ixx="0.006957590282"
        ixy="-0.0017011378" iyy="0.00993982268"
        ixz="-0.000029676183" iyz="0.000087952172" izz="0.012145140245" />
    </inertial>
    <visual>
      <origin xyz="0 0 0" rpy="0 0 3.1416" />
      <geometry>
        <mesh filename="package://rbq_description/meshes/stl/hip3.stl" scale="1 1 1"/>
      </geometry>
        <material name="white">
          <color rgba="0.9334 0.91 0.667 1.0" />
        </material>
    </visual>
  </link>

  <link name="HR_thigh">
    <inertial>
      <origin xyz="-0.004765 -0.00441 -0.06311" rpy="0 0 0" />
      <mass value="1.80014" />
      <inertia
        ixx="0.018990787558"
        ixy="0.000045769435" iyy="0.019770882672"
        ixz="-0.001024809563" iyz="0.000510504233" izz="0.001828257915" />
    </inertial>
    <collision>
      <origin xyz="0 0 0" rpy="1.57 0 0"/>
      <geometry>
        <cylinder length="0.07" radius="0.06"/>
      </geometry>
    </collision>
    <collision>
      <origin rpy="0 0 0" xyz="-0.035 0 -0.125" />
      <geometry>
        <box size="0.05 0.04 0.25" />
      </geometry>
    </collision>
    <visual>
      <origin xyz="0 0 0" rpy="0 0 0" />
      <geometry>
        <mesh filename="package://rbq_description/meshes/stl/thigh.stl" scale="1 1 1"/>
      </geometry>
        <material name="black">
          <color rgba="0.75294 0.75294 0.75294 1" />
        </material>
    </visual>
  </link>

  <link name="HR_calf">
    <inertial>
      <origin xyz="0.008988 0.000072 -0.14911" rpy="0 0 0" />
      <mass value="0.4520" />
      <inertia
        ixx="0.00428512"
        ixy="0.000000075939" iyy="0.00433136"
        ixz="0.0000230368745" iyz="0.000009344688" izz="0.0000616440919" />
    </inertial>
    <collision>
      <origin xyz="0 0 -0.065" rpy="0 -0.226893 0"/>
      <geometry>
        <box size="0.02 0.03 0.21"/>
      </geometry>
    </collision>
    <collision>
      <origin xyz="0.02 0 -0.23" rpy="0 0.11 0"/>
      <geometry>
        <box size="0.02 0.03 0.08"/>
      </geometry>
    </collision>
    <visual>
      <origin xyz="0 0 0" rpy="0 0 0" />
      <geometry>
        <mesh filename="package://rbq_description/meshes/stl/calf.STL" scale="1 1 1"/>
      </geometry>
        <material name="silver">
          <color rgba="0.3 0.3 0.3 1" />
        </material>
    </visual>
  </link>
  
  <link name="HR_foot">
    <inertial>
      <mass value="0.06"/>
      <inertia ixx="9.6e-06" ixy="0.0" ixz="0.0" iyy="9.6e-06" iyz="0.0" izz="9.6e-06"/>
    </inertial>
    <collision>
      <origin xyz="0 0 0" rpy="0 0 0" />
      <geometry>
        <sphere radius="0.03"/>
      </geometry>
    </collision>
  </link>

  <!-- ========== HL ========== -->
  <link name="HL_hip">
    <inertial>
      <origin xyz="0.027522 0.01681 -0.00187" rpy="0 0 0" />
      <mass value="3.669344" />
      <inertia
        ixx="0.006957590282"
        ixy="0.0017011378" iyy="0.00993982268"
        ixz="-0.000029676183" iyz="-0.000087952172" izz="0.012145140245" />
    </inertial>
    <visual>
      <origin xyz="0 0 0" rpy="0 0 3.141592" />
      <geometry>
        <mesh filename="package://rbq_description/meshes/stl/hip2.stl" scale="1 1 1"/>
      </geometry>
        <material name="white">
          <color rgba="0.9334 0.91 0.667 1.0" />
        </material>
    </visual>
  </link>

  <link name="HL_thigh">
    <inertial>
      <origin xyz="-0.004765 0.00441 -0.06311" rpy="0 0 0" />
      <mass value="1.80014" />
      <inertia
        ixx="0.018990787558"
        ixy="-0.000045769435" iyy="0.019770882672"
        ixz="-0.001024809563" iyz="-0.000510504233" izz="0.001828257915" />
    </inertial>
    <collision>
      <origin xyz="0 0 0" rpy="1.57 0 0"/>
      <geometry>
        <cylinder length="0.07" radius="0.06"/>
      </geometry>
    </collision>
    <collision>
      <origin rpy="0 0 0" xyz="-0.035 0 -0.125" />
      <geometry>
        <box size="0.05 0.04 0.25" />
      </geometry>
    </collision>
    <visual>
      <origin xyz="0 0 0" rpy="0 0 0" />
      <geometry>
        <mesh filename="package://rbq_description/meshes/stl/thigh.stl" scale="1 1 1"/>
      </geometry>
        <material name="black">
          <color rgba="0.75294 0.75294 0.75294 1" />
        </material>
    </visual>
  </link>

  <link name="HL_calf">
    <inertial>
      <origin xyz="0.008988 -0.000072 -0.14911" rpy="0 0 0" />
      <mass value="0.4520" />
      <inertia
        ixx="0.00428512"
        ixy="-0.000000075939" iyy="0.00433136"
        ixz="0.0000230368745" iyz="-0.000009344688" izz="0.0000616440919" />
    </inertial>
    <collision>
      <origin xyz="0 0 -0.065" rpy="0 -0.226893 0"/>
      <geometry>
        <box size="0.02 0.03 0.21"/>
      </geometry>
    </collision>
    <collision>
      <origin xyz="0.02 0 -0.23" rpy="0 0.11 0"/>
      <geometry>
        <box size="0.02 0.03 0.08"/>
      </geometry>
    </collision>
    <visual>
      <origin xyz="0 0 0" rpy="0 0 0" />
      <geometry>
        <mesh filename="package://rbq_description/meshes/stl/calf.STL" scale="1 1 1"/>
      </geometry>
        <material name="silver">
          <color rgba="0.3 0.3 0.3 1" />
        </material>
    </visual>
  </link>

  <link name="HL_foot">
    <inertial>
      <mass value="0.06"/>
      <inertia ixx="9.6e-06" ixy="0.0" ixz="0.0" iyy="9.6e-06" iyz="0.0" izz="9.6e-06"/>
    </inertial>
    <collision>
      <origin xyz="0 0 0" rpy="0 0 0" />
      <geometry>
        <sphere radius="0.03"/>
      </geometry>
    </collision>
  </link>


  <!-- ========== FR ========== -->
  <link name="FR_hip">
    <inertial>
      <origin xyz="-0.027522 -0.01681 -0.00187" rpy="0 0 0" />
      <mass value="3.669344" />
      <inertia
        ixx="0.006957590282"
        ixy="0.0017011378" iyy="0.00993982268"
        ixz="0.000029676183" iyz="0.000087952172" izz="0.012145140245" />
    </inertial>
    <visual>
      <origin xyz="0 0 0" rpy="0 0 0" />
      <geometry>
        <mesh filename="package://rbq_description/meshes/stl/hip2.stl" scale="1 1 1"/>
      </geometry>
        <material name="white">
          <color rgba="0.9334 0.91 0.667 1.0" />
        </material>
    </visual>
  </link>

  <link name="FR_thigh">
    <inertial>
      <origin xyz="-0.004765 -0.00441 -0.06311" rpy="0 0 0" />
      <mass value="1.80014" />
      <inertia
        ixx="0.018990787558"
        ixy="0.000045769435" iyy="0.019770882672"
        ixz="-0.001024809563" iyz="0.000510504233" izz="0.001828257915" />
    </inertial>
    <collision>
      <origin xyz="0 0 0" rpy="1.57 0 0"/>
      <geometry>
        <cylinder length="0.07" radius="0.06"/>
      </geometry>
    </collision>
    <collision>
      <origin rpy="0 0 0" xyz="-0.035 0 -0.125" />
      <geometry>
        <box size="0.05 0.04 0.25" />
      </geometry>
    </collision>
    <visual>
      <origin xyz="0 0 0" rpy="0 0 0" />
      <geometry>
        <mesh filename="package://rbq_description/meshes/stl/thigh.stl" scale="1 1 1"/>
      </geometry>
        <material name="black">
          <color rgba="0.75294 0.75294 0.75294 1" />
        </material>
    </visual>
  </link>

  <link name="FR_calf">
    <inertial>
      <origin xyz="0.008988 0.000072 -0.14911" rpy="0 0 0" />
      <mass value="0.4520" />
      <inertia
        ixx="0.00428512"
        ixy="0.000000075939" iyy="0.00433136"
        ixz="0.0000230368745" iyz="0.000009344688" izz="0.0000616440919" />
    </inertial>
    <collision>
      <origin xyz="0 0 -0.065" rpy="0 -0.226893 0"/>
      <geometry>
        <box size="0.02 0.03 0.21"/>
      </geometry>
    </collision>
    <collision>
      <origin xyz="0.02 0 -0.23" rpy="0 0.11 0"/>
      <geometry>
        <box size="0.02 0.03 0.08"/>
      </geometry>
    </collision>
    <visual>
      <origin xyz="0 0 0" rpy="0 0 0" />
      <geometry>
        <mesh filename="package://rbq_description/meshes/stl/calf.STL" scale="1 1 1"/>
      </geometry>
        <material name="silver">
          <color rgba="0.3 0.3 0.3 1" />
        </material>
    </visual>
  </link>
  
  <link name="FR_foot">
    <inertial>
      <mass value="0.06"/>
      <inertia ixx="9.6e-06" ixy="0.0" ixz="0.0" iyy="9.6e-06" iyz="0.0" izz="9.6e-06"/>
    </inertial>
    <collision>
      <origin xyz="0 0 0" rpy="0 0 0" />
      <geometry>
        <sphere radius="0.03"/>
      </geometry>
    </collision>
  </link>


  <!-- ========== FL ========== -->
  <link name="FL_hip">
    <inertial>
      <origin xyz="-0.027522 0.01681 -0.00187" rpy="0 0 0" />
      <mass value="3.669344" />
      <inertia
        ixx="0.006957590282"
        ixy="-0.0017011378" iyy="0.00993982268"
        ixz="0.000029676183" iyz="-0.000087952172" izz="0.012145140245" />
    </inertial>
    <visual>
      <origin xyz="0 0 0" rpy="0 0 0" />
      <geometry>
        <mesh filename="package://rbq_description/meshes/stl/hip3.stl" scale="1 1 1"/>
      </geometry>
        <material name="white">
          <color rgba="0.9334 0.91 0.667 1.0" />
        </material>
    </visual>
  </link>

  <link name="FL_thigh">
    <inertial>
      <origin xyz="-0.004765 0.00441 -0.06311" rpy="0 0 0" />
      <mass value="1.80014" />
      <inertia
        ixx="0.018990787558"
        ixy="-0.000045769435" iyy="0.019770882672"
        ixz="-0.001024809563" iyz="-0.000510504233" izz="0.001828257915" />
    </inertial>
    <collision>
      <origin xyz="0 0 0" rpy="1.57 0 0"/>
      <geometry>
        <cylinder length="0.07" radius="0.06"/>
      </geometry>
    </collision>
    <collision>
      <origin rpy="0 0 0" xyz="-0.035 0 -0.125" />
      <geometry>
        <box size="0.05 0.04 0.25" />
      </geometry>
    </collision>
    <visual>
      <origin xyz="0 0 0" rpy="0 0 0" />
      <geometry>
        <mesh filename="package://rbq_description/meshes/stl/thigh.stl" scale="1 1 1"/>
      </geometry>
        <material name="black">
          <color rgba="0.75294 0.75294 0.75294 1" />
        </material>
    </visual>
  </link>

  <link name="FL_calf">
    <inertial>
      <origin xyz="0.008988 -0.000072 -0.14911" rpy="0 0 0" />
      <mass value="0.4520" />
      <inertia
        ixx="0.00428512"
        ixy="-0.000000075939" iyy="0.00433136"
        ixz="0.0000230368745" iyz="-0.000009344688" izz="0.0000616440919" />
    </inertial>
    <collision>
      <origin xyz="0 0 -0.065" rpy="0 -0.226893 0"/>
      <geometry>
        <box size="0.02 0.03 0.21"/>
      </geometry>
    </collision>
    <collision>
      <origin xyz="0.02 0 -0.23" rpy="0 0.11 0"/>
      <geometry>
        <box size="0.02 0.03 0.08"/>
      </geometry>
    </collision>
    <visual>
      <origin xyz="0 0 0" rpy="0 0 0" />
      <geometry>
        <mesh filename="package://rbq_description/meshes/stl/calf.STL" scale="1 1 1"/>
      </geometry>
        <material name="silver">
          <color rgba="0.3 0.3 0.3 1" />
        </material>
    </visual>
  </link>

  <link name="FL_foot">
    <inertial>
      <mass value="0.06"/>
      <inertia ixx="9.6e-06" ixy="0.0" ixz="0.0" iyy="9.6e-06" iyz="0.0" izz="9.6e-06"/>
    </inertial>
    <collision>
      <origin xyz="0 0 0" rpy="0 0 0" />
      <geometry>
        <sphere radius="0.03"/>
      </geometry>
    </collision>
  </link>


 <!-- ===== JOINT ===== -->
  <joint name="joint0_HRR" type="revolute">
    <origin xyz="-0.31218 -0.09 0" rpy="0 0 0" />
    <parent link="trunk" />
    <child link="HR_hip" />
    <axis xyz="1 0 0" />
    <dynamics damping="0" friction="0" rotor_inertia="0.014058"/>
    <limit effort="100"  velocity="50" lower="-0.7330" upper="0.5411" />
  </joint>

  <joint name="joint1_HRP" type="revolute">
    <origin xyz="0 -0.10285 0" rpy="0 0 0" />
    <parent link="HR_hip" />
    <child link="HR_thigh" />
    <axis xyz="0 1 0" />
    <dynamics damping="0" friction="0" rotor_inertia="0.014058"/>
    <limit effort="100" velocity="50" lower="-6.2832" upper="6.2832"/>
  </joint>

  <joint name="joint2_HRK" type="revolute">
    <origin xyz="0 0 -0.33" rpy="0 0 0" />
    <parent link="HR_thigh" />
    <child link="HR_calf" />
    <axis xyz="0 1 0" />
    <dynamics damping="0" friction="0" rotor_inertia="0.0214816"/>
    <limit effort="150"  velocity="50" lower="-2.8274" upper="-0.4189" />
  </joint>

  <joint name="foot_joint_HRF" type="fixed" dont_collapse="true">
    <origin xyz="0 0 -0.33" rpy="0 0 0" />
    <parent link="HR_calf" />
    <child link="HR_foot" />
  </joint>

  <joint name="joint3_HLR" type="revolute">
    <origin xyz="-0.31218 0.09 0" rpy="0 0 0" />
    <parent link="trunk" />
    <child link="HL_hip" />
    <axis xyz="1 0 0" />
    <dynamics damping="0" friction="0" rotor_inertia="0.014058"/>
    <limit effort="100"  velocity="50" lower="-0.5411" upper="0.7330" />
  </joint>

  <joint name="joint4_HLP" type="revolute">
    <origin xyz="0 0.10285 0" rpy="0 0 0" />
    <parent link="HL_hip" />
    <child link="HL_thigh" />
    <axis xyz="0 1 0" />
    <dynamics damping="0" friction="0" rotor_inertia="0.014058"/>
    <limit effort="100" velocity="50" lower="-6.2832" upper="6.2832"/>
  </joint>

  <joint name="joint5_HLK" type="revolute">
    <origin xyz="0 0 -0.33" rpy="0 0 0" />
    <parent link="HL_thigh" />
    <child link="HL_calf" />
    <axis xyz="0 1 0" />
    <dynamics damping="0" friction="0" rotor_inertia="0.0214816"/>
    <limit effort="150"  velocity="50" lower="-2.8274" upper="-0.4189" />
  </joint>

  <joint name="foot_joint_HLF" type="fixed" dont_collapse="true">
    <origin xyz="0 0 -0.33" rpy="0 0 0" />
    <parent link="HL_calf" />
    <child link="HL_foot" />
  </joint>

  <joint name="joint6_FRR" type="revolute">
    <origin xyz="0.31218 -0.09 0" rpy="0 0 0" />
    <parent link="trunk" />
    <child link="FR_hip" />
    <axis xyz="1 0 0" />
    <dynamics damping="0" friction="0" rotor_inertia="0.014058"/>
    <limit effort="100"  velocity="50" lower="-0.7330" upper="0.5411" />
  </joint>

  <joint name="joint7_FRP" type="revolute">
    <origin xyz="0 -0.10285 0" rpy="0 0 0" />
    <parent link="FR_hip" />
    <child link="FR_thigh" />
    <axis xyz="0 1 0" />
    <dynamics damping="0" friction="0" rotor_inertia="0.014058"/>
    <limit effort="100" velocity="50" lower="-6.2832" upper="6.2832"/>
  </joint>

  <joint name="joint8_FRK" type="revolute">
    <origin xyz="0 0 -0.33" rpy="0 0 0" />
    <parent link="FR_thigh" />
    <child link="FR_calf" />
    <axis xyz="0 1 0" />
    <dynamics damping="0" friction="0" rotor_inertia="0.0214816"/>
    <limit effort="150"  velocity="50" lower="-2.8274" upper="-0.4189" />
  </joint>

  <joint name="foot_joint_FRF" type="fixed" dont_collapse="true">
    <origin xyz="0 0 -0.33" rpy="0 0 0" />
    <parent link="FR_calf" />
    <child link="FR_foot" />
  </joint>
  
  <joint name="joint9_FLR" type="revolute">
    <origin xyz="0.31218 0.09 0" rpy="0 0 0" />
    <parent link="trunk" />
    <child link="FL_hip" />
    <axis xyz="1 0 0" />
    <dynamics damping="0" friction="0" rotor_inertia="0.014058"/>
    <limit effort="100"  velocity="50" lower="-0.5411" upper="0.7330" />
  </joint>

  <joint name="joint10_FLP" type="revolute">
    <origin xyz="0 0.10285 0" rpy="0 0 0" />
    <parent link="FL_hip" />
    <child link="FL_thigh" />
    <axis xyz="0 1 0" />
    <dynamics damping="0" friction="0" rotor_inertia="0.014058"/>
    <limit effort="100" velocity="50" lower="-6.2832" upper="6.2832"/>
  </joint>

  <joint name="joint11_FLK" type="revolute">
    <origin xyz="0 0 -0.33" rpy="0 0 0" />
    <parent link="FL_thigh" />
    <child link="FL_calf" />
    <axis xyz="0 1 0" />
    <dynamics damping="0" friction="0" rotor_inertia="0.0214816" />
    <limit effort="150"  velocity="50" lower="-2.8274" upper="-0.4189" />
  </joint>

  <joint name="foot_joint_FLF" type="fixed" dont_collapse="true">
    <origin xyz="0 0 -0.33" rpy="0 0 0" />
    <parent link="FL_calf" />
    <child link="FL_foot" />
  </joint>

</robot>